<?xml version="1.0" ?>
<!-- =================================================================================== -->
<!-- |    This document was autogenerated by xacro from model.urdf.xacro               | -->
<!-- |    EDITING THIS FILE BY HAND IS NOT RECOMMENDED                                 | -->
<!-- =================================================================================== -->
<robot name="wheele">
  <!-- Specify some standard inertial calculations https://en.wikipedia.org/wiki/List_of_moments_of_inertia -->
  <!-- These make use of xacro's mathematical functionality -->
  <material name="white">
    <color rgba="1 1 1 1"/>
  </material>
  <material name="orange">
    <color rgba="1 0.3 0.1 1"/>
  </material>
  <material name="blue">
    <color rgba="0.2 0.2 1 1"/>
  </material>
  <material name="black">
    <color rgba="0 0 0 1"/>
  </material>
  <material name="red">
    <color rgba="1 0 0 1"/>
  </material>
  <!-- MACRO FOR THE WHEELS -->
  <!-- BASE LINK -->
  <link name="base_link">

    </link>
  <!-- BASE_FOOTPRINT LINK -->
  <joint name="base_footprint_joint" type="fixed">
    <parent link="base_link"/>
    <child link="base_footprint"/>
    <origin rpy="0 0 0" xyz="0 0 0"/>
  </joint>
  <link name="base_footprint">
    </link>
  <!-- CHASSIS LINK -->
  <joint name="chassis_joint" type="fixed">
    <parent link="base_link"/>
    <child link="chassis"/>
    <origin xyz="0 0 0"/>
  </joint>
  <link name="chassis">
    <visual>
      <origin rpy="0 0 1.5707963267948966" xyz="0 0 0"/>
      <geometry>
        <mesh filename="file:/home/davide-work/humble_ws/wheele/src/wheele_model/description/src/wheele_model/description/mesh/body_robot_2.dae" scale="1 1 1"/>
      </geometry>
      <material name="orange"/>
    </visual>
    <collision>
      <origin xyz="0 0 0.0965"/>
      <geometry>
        <box size="0.558 0.313 0.193"/>
      </geometry>
    </collision>
    <inertial>
      <origin rpy="0 0 0" xyz="0 0 0.0965"/>
      <mass value="0.5"/>
      <inertia ixx="0.005634083333333333" ixy="0.0" ixz="0.0" iyy="0.01452554166666667" iyz="0.0" izz="0.017055541666666667"/>
    </inertial>
  </link>
  <gazebo reference="chassis">
    <material>Gazebo/Orange</material>
  </gazebo>
  <joint name="base_to_front_right_steering" type="continuous">
    <parent link="base_link"/>
    <child link="front_right_steering"/>
    <origin rpy="0 0 0" xyz="0.1565 0.29050000000000004 0"/>
    <axis xyz="0 0 1"/>
  </joint>
  <!-- fake link to simulate the steering-->
  <link name="front_right_steering">
    <inertial>
      <mass value="0.0005"/>
      <inertia ixx="0.0000018" ixy="0.0" ixz="0.0" iyy="0.0000018" iyz="0.0" izz="0.0000018"/>
    </inertial>
  </link>
  <joint name="steering_to_front_right_wheel" type="continuous">
    <parent link="front_right_steering"/>
    <child link="front_right_wheel"/>
    <origin rpy="0 0 0" xyz="0 0 0.07"/>
    <axis xyz="0 1 0"/>
  </joint>
  <link name="front_right_wheel">
    <visual>
      <geometry>
        <mesh filename="file:/home/davide-work/humble_ws/wheele/src/wheele_model/description/src/wheele_model/description/mesh/Wheel.dae" scale="1 1 1"/>
      </geometry>
      <origin rpy="0 0 3.141592653589793" xyz="0 0 0"/>
      <material name="white"/>
    </visual>
    <collision>
      <geometry>
        <cylinder length="0.085" radius="0.07"/>
      </geometry>
      <origin rpy="1.5707963267948966 0 0" xyz="0 0 0"/>
    </collision>
    <inertial>
      <origin rpy="0 0 0" xyz="0 0 0"/>
      <mass value="0.05"/>
      <inertia ixx="9.135416666666668e-05" ixy="0.0" ixz="0.0" iyy="9.135416666666668e-05" iyz="0.0" izz="0.00012250000000000002"/>
    </inertial>
  </link>
  <gazebo reference="front_right_wheel">
    <material>Gazebo/Blue</material>
  </gazebo>
  <joint name="base_to_front_left_steering" type="continuous">
    <parent link="base_link"/>
    <child link="front_left_steering"/>
    <origin rpy="0 0 0" xyz="0.1565 -0.29050000000000004 0"/>
    <axis xyz="0 0 1"/>
  </joint>
  <!-- fake link to simulate the steering-->
  <link name="front_left_steering">
    <inertial>
      <mass value="0.0005"/>
      <inertia ixx="0.0000018" ixy="0.0" ixz="0.0" iyy="0.0000018" iyz="0.0" izz="0.0000018"/>
    </inertial>
  </link>
  <joint name="steering_to_front_left_wheel" type="continuous">
    <parent link="front_left_steering"/>
    <child link="front_left_wheel"/>
    <origin rpy="0 0 0" xyz="0 0 0.07"/>
    <axis xyz="0 1 0"/>
  </joint>
  <link name="front_left_wheel">
    <visual>
      <geometry>
        <mesh filename="file:/home/davide-work/humble_ws/wheele/src/wheele_model/description/src/wheele_model/description/mesh/Wheel.dae" scale="1 1 1"/>
      </geometry>
      <origin rpy="0 0 0.0" xyz="0 0 0"/>
      <material name="white"/>
    </visual>
    <collision>
      <geometry>
        <cylinder length="0.085" radius="0.07"/>
      </geometry>
      <origin rpy="1.5707963267948966 0 0" xyz="0 0 0"/>
    </collision>
    <inertial>
      <origin rpy="0 0 0" xyz="0 0 0"/>
      <mass value="0.05"/>
      <inertia ixx="9.135416666666668e-05" ixy="0.0" ixz="0.0" iyy="9.135416666666668e-05" iyz="0.0" izz="0.00012250000000000002"/>
    </inertial>
  </link>
  <gazebo reference="front_left_wheel">
    <material>Gazebo/Blue</material>
  </gazebo>
  <joint name="base_to_rear_right_steering" type="continuous">
    <parent link="base_link"/>
    <child link="rear_right_steering"/>
    <origin rpy="0 0 0" xyz="-0.1565 0.29050000000000004 0"/>
    <axis xyz="0 0 1"/>
  </joint>
  <!-- fake link to simulate the steering-->
  <link name="rear_right_steering">
    <inertial>
      <mass value="0.0005"/>
      <inertia ixx="0.0000018" ixy="0.0" ixz="0.0" iyy="0.0000018" iyz="0.0" izz="0.0000018"/>
    </inertial>
  </link>
  <joint name="steering_to_rear_right_wheel" type="continuous">
    <parent link="rear_right_steering"/>
    <child link="rear_right_wheel"/>
    <origin rpy="0 0 0" xyz="0 0 0.07"/>
    <axis xyz="0 1 0"/>
  </joint>
  <link name="rear_right_wheel">
    <visual>
      <geometry>
        <mesh filename="file:/home/davide-work/humble_ws/wheele/src/wheele_model/description/src/wheele_model/description/mesh/Wheel.dae" scale="1 1 1"/>
      </geometry>
      <origin rpy="0 0 3.141592653589793" xyz="0 0 0"/>
      <material name="white"/>
    </visual>
    <collision>
      <geometry>
        <cylinder length="0.085" radius="0.07"/>
      </geometry>
      <origin rpy="1.5707963267948966 0 0" xyz="0 0 0"/>
    </collision>
    <inertial>
      <origin rpy="0 0 0" xyz="0 0 0"/>
      <mass value="0.05"/>
      <inertia ixx="9.135416666666668e-05" ixy="0.0" ixz="0.0" iyy="9.135416666666668e-05" iyz="0.0" izz="0.00012250000000000002"/>
    </inertial>
  </link>
  <gazebo reference="rear_right_wheel">
    <material>Gazebo/Blue</material>
  </gazebo>
  <joint name="base_to_rear_left_steering" type="continuous">
    <parent link="base_link"/>
    <child link="rear_left_steering"/>
    <origin rpy="0 0 0" xyz="-0.1565 -0.29050000000000004 0"/>
    <axis xyz="0 0 1"/>
  </joint>
  <!-- fake link to simulate the steering-->
  <link name="rear_left_steering">
    <inertial>
      <mass value="0.0005"/>
      <inertia ixx="0.0000018" ixy="0.0" ixz="0.0" iyy="0.0000018" iyz="0.0" izz="0.0000018"/>
    </inertial>
  </link>
  <joint name="steering_to_rear_left_wheel" type="continuous">
    <parent link="rear_left_steering"/>
    <child link="rear_left_wheel"/>
    <origin rpy="0 0 0" xyz="0 0 0.07"/>
    <axis xyz="0 1 0"/>
  </joint>
  <link name="rear_left_wheel">
    <visual>
      <geometry>
        <mesh filename="file:/home/davide-work/humble_ws/wheele/src/wheele_model/description/src/wheele_model/description/mesh/Wheel.dae" scale="1 1 1"/>
      </geometry>
      <origin rpy="0 0 0.0" xyz="0 0 0"/>
      <material name="white"/>
    </visual>
    <collision>
      <geometry>
        <cylinder length="0.085" radius="0.07"/>
      </geometry>
      <origin rpy="1.5707963267948966 0 0" xyz="0 0 0"/>
    </collision>
    <inertial>
      <origin rpy="0 0 0" xyz="0 0 0"/>
      <mass value="0.05"/>
      <inertia ixx="9.135416666666668e-05" ixy="0.0" ixz="0.0" iyy="9.135416666666668e-05" iyz="0.0" izz="0.00012250000000000002"/>
    </inertial>
  </link>
  <gazebo reference="rear_left_wheel">
    <material>Gazebo/Blue</material>
  </gazebo>
  <!-- LEFT WHEEL LINK 

    <joint name="left_wheel_joint" type="continuous">
        <parent link="base_link"/>
        <child link="left_wheel"/>
        <origin xyz="0 ${wheel_offset_y} 0" rpy="-${pi/2} 0 0" />
        <axis xyz="0 0 1"/>
    </joint>

    <link name="left_wheel">
        <visual>
            <geometry>
                <cylinder radius="${wheel_radius}" length="${wheel_thickness}"/>
            </geometry>
            <material name="blue"/>
        </visual>
        <collision>
            <geometry>
                <sphere radius="${wheel_radius}"/>
            </geometry>
        </collision>
        <xacro:inertial_cylinder mass="${wheel_mass}" length="${wheel_thickness}" radius="${wheel_radius}">
            <origin xyz="0 0 0" rpy="0 0 0"/>
        </xacro:inertial_cylinder>
    </link>

    <gazebo reference="left_wheel">
        <material>Gazebo/Blue</material>
    </gazebo>

-->
  <!-- RIGHT WHEEL LINK 

    <joint name="right_wheel_joint" type="continuous">
        <parent link="base_link"/>
        <child link="right_wheel"/>
        <origin xyz="0 ${-wheel_offset_y} 0" rpy="${pi/2} 0 0" />
        <axis xyz="0 0 -1"/>
    </joint>

    <link name="right_wheel">
        <visual>
            <geometry>
                <cylinder radius="${wheel_radius}" length="${wheel_thickness}"/>
            </geometry>
            <material name="blue"/>
        </visual>
        <collision>
            <geometry>
                <sphere radius="${wheel_radius}"/>
            </geometry>
        </collision>
        <xacro:inertial_cylinder mass="${wheel_mass}" length="${wheel_thickness}" radius="${wheel_radius}">
            <origin xyz="0 0 0" rpy="0 0 0"/>
        </xacro:inertial_cylinder>
    </link>

    <gazebo reference="right_wheel">
        <material>Gazebo/Blue</material>
    </gazebo>
-->
  <!-- CASTER WHEEL LINK -->
  <gazebo>
    <plugin filename="gz-sim-ackermann-steering-system" name="gz::sim::systems::AckermannSteering">
      <left_joint>steering_to_front_left_wheel</left_joint>
      <left_joint>steering_to_rear_left_wheel</left_joint>
      <right_joint>steering_to_front_right_wheel</right_joint>
      <right_joint>steering_to_rear_right_wheel</right_joint>
      <left_steering_joint>base_to_front_left_steering</left_steering_joint>
      <right_steering_joint>base_to_front_right_steering</right_steering_joint>
      <kingpin_width>.18</kingpin_width>
      <steering_limit>0.5</steering_limit>
      <wheel_base>.31</wheel_base>
      <wheel_separation>.3</wheel_separation>
      <wheel_radius>0.075</wheel_radius>
      <min_velocity>-100</min_velocity>
      <max_velocity>100</max_velocity>
      <min_acceleration>-5</min_acceleration>
      <max_acceleration>5</max_acceleration>
      <topic>/model/base_link/cmd_vel0</topic>
    </plugin>
    <plugin filename="gz-sim-ackermann-steering-system" name="gz::sim::systems::AckermannSteering">
      <left_joint>steering_to_front_left_wheel</left_joint>
      <left_joint>steering_to_rear_left_wheel</left_joint>
      <right_joint>steering_to_front_right_wheel</right_joint>
      <right_joint>steering_to_rear_right_wheel</right_joint>
      <left_steering_joint>base_to_rear_left_steering</left_steering_joint>
      <right_steering_joint>base_to_rear_right_steering</right_steering_joint>
      <kingpin_width>.18</kingpin_width>
      <steering_limit>0.5</steering_limit>
      <wheel_base>.31</wheel_base>
      <wheel_separation>.3</wheel_separation>
      <wheel_radius>0.075</wheel_radius>
      <min_velocity>-100</min_velocity>
      <max_velocity>100</max_velocity>
      <min_acceleration>-5</min_acceleration>
      <max_acceleration>5</max_acceleration>
      <topic>/model/base_link/cmd_vel1</topic>
    </plugin>
    <plugin filename="gz-sim-joint-state-publisher-system" name="gz::sim::systems::JointStatePublisher">
        </plugin>
    <plugin filename="gz-sim-pose-publisher-system" name="gz::sim::systems::PosePublisher">
      <use_pose_vector_msg>true</use_pose_vector_msg>
      <static_publisher>true</static_publisher>
      <static_update_frequency>1</static_update_frequency>
      <publish_link_pose>true</publish_link_pose>
      <publish_sensor_pose>true</publish_sensor_pose>
      <publish_collision_pose>false</publish_collision_pose>
      <publish_visual_pose>false</publish_visual_pose>
      <publish_nested_model_pose>true</publish_nested_model_pose>
      <!-- this bit is important -->
      <use_pose_vector_msg>true</use_pose_vector_msg>
      <static_publisher>true</static_publisher>
      <static_update_frequency>1</static_update_frequency>
    </plugin>
    <plugin filename="gz-sim-odometry-publisher-system" name="gz::sim::systems::OdometryPublisher">
      <odom_frame>odom</odom_frame>
      <odom_topic>/odom</odom_topic>
      <robot_base_frame>base_link</robot_base_frame>
    </plugin>
  </gazebo>
</robot>
