<?xml version="1.0" ?>
<!-- =================================================================================== -->
<!-- |    This document was autogenerated by xacro from model.urdf.xacro               | -->
<!-- |    EDITING THIS FILE BY HAND IS NOT RECOMMENDED                                 | -->
<!-- =================================================================================== -->
<robot name="wheele">
  <!-- Specify some standard inertial calculations https://en.wikipedia.org/wiki/List_of_moments_of_inertia -->
  <!-- These make use of xacro's mathematical functionality -->
  <material name="white">
    <color rgba="1 1 1 1"/>
  </material>
  <material name="orange">
    <color rgba="1 0.3 0.1 1"/>
  </material>
  <material name="blue">
    <color rgba="0.2 0.2 1 1"/>
  </material>
  <material name="black">
    <color rgba="0 0 0 1"/>
  </material>
  <material name="red">
    <color rgba="1 0 0 1"/>
  </material>
  <!-- MACRO FOR THE WHEELS -->
  <!-- BASE LINK -->
  <link name="base_footprint">
    </link>
  <!-- BASE_FOOTPRINT LINK -->
  <joint name="base_footprint_joint" type="fixed">
    <parent link="base_footprint"/>
    <child link="base_link"/>
    <origin rpy="0 0 0" xyz="0 0 0"/>
  </joint>
  <link name="base_link">

    </link>
  <!-- CHASSIS LINK -->
  <joint name="chassis_joint" type="fixed">
    <parent link="base_link"/>
    <child link="chassis"/>
    <origin xyz="0 0 0"/>
  </joint>
  <link name="chassis">
    <visual>
      <origin rpy="0 0 1.5707963267948966" xyz="0 0 0"/>
      <geometry>
        <mesh filename="file:/home/davide-work/humble_ws/wheele/src/wheele_model/description/src/wheele_model/description/mesh/body_robot_2.dae" scale="1 1 1"/>
      </geometry>
      <material name="orange"/>
    </visual>
    <collision>
      <origin xyz="0 0 0.0965"/>
      <geometry>
        <box size="0.558 0.313 0.193"/>
      </geometry>
    </collision>
    <inertial>
      <origin rpy="0 0 0" xyz="0 0 0.0965"/>
      <mass value="0.5"/>
      <inertia ixx="0.005634083333333333" ixy="0.0" ixz="0.0" iyy="0.01452554166666667" iyz="0.0" izz="0.017055541666666667"/>
    </inertial>
  </link>
  <gazebo reference="chassis">
    <material>Gazebo/Orange</material>
  </gazebo>
  <joint name="base_to_front_right_steering" type="continuous">
    <parent link="base_link"/>
    <child link="front_right_steering"/>
    <origin rpy="0 0 0" xyz="0.1565 0.29050000000000004 0"/>
    <axis xyz="0 0 1"/>
  </joint>
  <!-- fake link to simulate the steering-->
  <link name="front_right_steering">
    <inertial>
      <mass value="0.0005"/>
      <inertia ixx="0.0000018" ixy="0.0" ixz="0.0" iyy="0.0000018" iyz="0.0" izz="0.0000018"/>
    </inertial>
  </link>
  <joint name="steering_to_front_right_wheel" type="continuous">
    <parent link="front_right_steering"/>
    <child link="front_right_wheel"/>
    <origin rpy="0 0 0" xyz="0 0 0.07"/>
    <axis xyz="0 1 0"/>
  </joint>
  <link name="front_right_wheel">
    <visual>
      <geometry>
        <mesh filename="file:/home/davide-work/humble_ws/wheele/src/wheele_model/description/src/wheele_model/description/mesh/Wheel.dae" scale="1 1 1"/>
      </geometry>
      <origin rpy="0 0 3.141592653589793" xyz="0 0 0"/>
      <material name="white"/>
    </visual>
    <collision>
      <geometry>
        <cylinder length="0.085" radius="0.07"/>
      </geometry>
      <origin rpy="1.5707963267948966 0 0" xyz="0 0 0"/>
    </collision>
    <inertial>
      <origin rpy="0 0 0" xyz="0 0 0"/>
      <mass value="0.05"/>
      <inertia ixx="9.135416666666668e-05" ixy="0.0" ixz="0.0" iyy="9.135416666666668e-05" iyz="0.0" izz="0.00012250000000000002"/>
    </inertial>
  </link>
  <gazebo reference="front_right_wheel">
    <material>Gazebo/Blue</material>
  </gazebo>
  <joint name="base_to_front_left_steering" type="continuous">
    <parent link="base_link"/>
    <child link="front_left_steering"/>
    <origin rpy="0 0 0" xyz="0.1565 -0.29050000000000004 0"/>
    <axis xyz="0 0 1"/>
  </joint>
  <!-- fake link to simulate the steering-->
  <link name="front_left_steering">
    <inertial>
      <mass value="0.0005"/>
      <inertia ixx="0.0000018" ixy="0.0" ixz="0.0" iyy="0.0000018" iyz="0.0" izz="0.0000018"/>
    </inertial>
  </link>
  <joint name="steering_to_front_left_wheel" type="continuous">
    <parent link="front_left_steering"/>
    <child link="front_left_wheel"/>
    <origin rpy="0 0 0" xyz="0 0 0.07"/>
    <axis xyz="0 1 0"/>
  </joint>
  <link name="front_left_wheel">
    <visual>
      <geometry>
        <mesh filename="file:/home/davide-work/humble_ws/wheele/src/wheele_model/description/src/wheele_model/description/mesh/Wheel.dae" scale="1 1 1"/>
      </geometry>
      <origin rpy="0 0 0.0" xyz="0 0 0"/>
      <material name="white"/>
    </visual>
    <collision>
      <geometry>
        <cylinder length="0.085" radius="0.07"/>
      </geometry>
      <origin rpy="1.5707963267948966 0 0" xyz="0 0 0"/>
    </collision>
    <inertial>
      <origin rpy="0 0 0" xyz="0 0 0"/>
      <mass value="0.05"/>
      <inertia ixx="9.135416666666668e-05" ixy="0.0" ixz="0.0" iyy="9.135416666666668e-05" iyz="0.0" izz="0.00012250000000000002"/>
    </inertial>
  </link>
  <gazebo reference="front_left_wheel">
    <material>Gazebo/Blue</material>
  </gazebo>
  <joint name="base_to_rear_right_steering" type="continuous">
    <parent link="base_link"/>
    <child link="rear_right_steering"/>
    <origin rpy="0 0 0" xyz="-0.1565 0.29050000000000004 0"/>
    <axis xyz="0 0 1"/>
  </joint>
  <!-- fake link to simulate the steering-->
  <link name="rear_right_steering">
    <inertial>
      <mass value="0.0005"/>
      <inertia ixx="0.0000018" ixy="0.0" ixz="0.0" iyy="0.0000018" iyz="0.0" izz="0.0000018"/>
    </inertial>
  </link>
  <joint name="steering_to_rear_right_wheel" type="continuous">
    <parent link="rear_right_steering"/>
    <child link="rear_right_wheel"/>
    <origin rpy="0 0 0" xyz="0 0 0.07"/>
    <axis xyz="0 1 0"/>
  </joint>
  <link name="rear_right_wheel">
    <visual>
      <geometry>
        <mesh filename="file:/home/davide-work/humble_ws/wheele/src/wheele_model/description/src/wheele_model/description/mesh/Wheel.dae" scale="1 1 1"/>
      </geometry>
      <origin rpy="0 0 3.141592653589793" xyz="0 0 0"/>
      <material name="white"/>
    </visual>
    <collision>
      <geometry>
        <cylinder length="0.085" radius="0.07"/>
      </geometry>
      <origin rpy="1.5707963267948966 0 0" xyz="0 0 0"/>
    </collision>
    <inertial>
      <origin rpy="0 0 0" xyz="0 0 0"/>
      <mass value="0.05"/>
      <inertia ixx="9.135416666666668e-05" ixy="0.0" ixz="0.0" iyy="9.135416666666668e-05" iyz="0.0" izz="0.00012250000000000002"/>
    </inertial>
  </link>
  <gazebo reference="rear_right_wheel">
    <material>Gazebo/Blue</material>
  </gazebo>
  <joint name="base_to_rear_left_steering" type="continuous">
    <parent link="base_link"/>
    <child link="rear_left_steering"/>
    <origin rpy="0 0 0" xyz="-0.1565 -0.29050000000000004 0"/>
    <axis xyz="0 0 1"/>
  </joint>
  <!-- fake link to simulate the steering-->
  <link name="rear_left_steering">
    <inertial>
      <mass value="0.0005"/>
      <inertia ixx="0.0000018" ixy="0.0" ixz="0.0" iyy="0.0000018" iyz="0.0" izz="0.0000018"/>
    </inertial>
  </link>
  <joint name="steering_to_rear_left_wheel" type="continuous">
    <parent link="rear_left_steering"/>
    <child link="rear_left_wheel"/>
    <origin rpy="0 0 0" xyz="0 0 0.07"/>
    <axis xyz="0 1 0"/>
  </joint>
  <link name="rear_left_wheel">
    <visual>
      <geometry>
        <mesh filename="file:/home/davide-work/humble_ws/wheele/src/wheele_model/description/src/wheele_model/description/mesh/Wheel.dae" scale="1 1 1"/>
      </geometry>
      <origin rpy="0 0 0.0" xyz="0 0 0"/>
      <material name="white"/>
    </visual>
    <collision>
      <geometry>
        <cylinder length="0.085" radius="0.07"/>
      </geometry>
      <origin rpy="1.5707963267948966 0 0" xyz="0 0 0"/>
    </collision>
    <inertial>
      <origin rpy="0 0 0" xyz="0 0 0"/>
      <mass value="0.05"/>
      <inertia ixx="9.135416666666668e-05" ixy="0.0" ixz="0.0" iyy="9.135416666666668e-05" iyz="0.0" izz="0.00012250000000000002"/>
    </inertial>
  </link>
  <gazebo reference="rear_left_wheel">
    <material>Gazebo/Blue</material>
  </gazebo>
  <!-- LEFT WHEEL LINK 

    <joint name="left_wheel_joint" type="continuous">
        <parent link="base_link"/>
        <child link="left_wheel"/>
        <origin xyz="0 ${wheel_offset_y} 0" rpy="-${pi/2} 0 0" />
        <axis xyz="0 0 1"/>
    </joint>

    <link name="left_wheel">
        <visual>
            <geometry>
                <cylinder radius="${wheel_radius}" length="${wheel_thickness}"/>
            </geometry>
            <material name="blue"/>
        </visual>
        <collision>
            <geometry>
                <sphere radius="${wheel_radius}"/>
            </geometry>
        </collision>
        <xacro:inertial_cylinder mass="${wheel_mass}" length="${wheel_thickness}" radius="${wheel_radius}">
            <origin xyz="0 0 0" rpy="0 0 0"/>
        </xacro:inertial_cylinder>
    </link>

    <gazebo reference="left_wheel">
        <material>Gazebo/Blue</material>
    </gazebo>

-->
  <!-- RIGHT WHEEL LINK 

    <joint name="right_wheel_joint" type="continuous">
        <parent link="base_link"/>
        <child link="right_wheel"/>
        <origin xyz="0 ${-wheel_offset_y} 0" rpy="${pi/2} 0 0" />
        <axis xyz="0 0 -1"/>
    </joint>

    <link name="right_wheel">
        <visual>
            <geometry>
                <cylinder radius="${wheel_radius}" length="${wheel_thickness}"/>
            </geometry>
            <material name="blue"/>
        </visual>
        <collision>
            <geometry>
                <sphere radius="${wheel_radius}"/>
            </geometry>
        </collision>
        <xacro:inertial_cylinder mass="${wheel_mass}" length="${wheel_thickness}" radius="${wheel_radius}">
            <origin xyz="0 0 0" rpy="0 0 0"/>
        </xacro:inertial_cylinder>
    </link>

    <gazebo reference="right_wheel">
        <material>Gazebo/Blue</material>
    </gazebo>
-->
  <!-- CASTER WHEEL LINK -->
  <gazebo>
    <plugin filename="gz-sim-ackermann-steering-system" name="gz::sim::systems::AckermannSteering">
      <left_joint>steering_to_front_left_wheel</left_joint>
      <left_joint>steering_to_rear_left_wheel</left_joint>
      <right_joint>steering_to_front_right_wheel</right_joint>
      <right_joint>steering_to_rear_right_wheel</right_joint>
      <left_steering_joint>base_to_front_left_steering</left_steering_joint>
      <right_steering_joint>base_to_front_right_steering</right_steering_joint>
      <kingpin_width>.18</kingpin_width>
      <steering_limit>0.5</steering_limit>
      <wheel_base>.31</wheel_base>
      <wheel_separation>.3</wheel_separation>
      <wheel_radius>0.075</wheel_radius>
      <min_velocity>-100</min_velocity>
      <max_velocity>100</max_velocity>
      <min_acceleration>-5</min_acceleration>
      <max_acceleration>5</max_acceleration>
      <topic>/cmd_vel0</topic>
    </plugin>
    <plugin filename="gz-sim-ackermann-steering-system" name="gz::sim::systems::AckermannSteering">
      <left_joint>steering_to_front_left_wheel</left_joint>
      <left_joint>steering_to_rear_left_wheel</left_joint>
      <right_joint>steering_to_front_right_wheel</right_joint>
      <right_joint>steering_to_rear_right_wheel</right_joint>
      <left_steering_joint>base_to_rear_left_steering</left_steering_joint>
      <right_steering_joint>base_to_rear_right_steering</right_steering_joint>
      <kingpin_width>.18</kingpin_width>
      <steering_limit>0.5</steering_limit>
      <wheel_base>.31</wheel_base>
      <wheel_separation>.3</wheel_separation>
      <wheel_radius>0.075</wheel_radius>
      <min_velocity>-100</min_velocity>
      <max_velocity>100</max_velocity>
      <min_acceleration>-5</min_acceleration>
      <max_acceleration>5</max_acceleration>
      <topic>/cmd_vel1</topic>
    </plugin>
    <plugin filename="gz-sim-joint-state-publisher-system" name="gz::sim::systems::JointStatePublisher">
        </plugin>
    <plugin filename="gz-sim-pose-publisher-system" name="gz::sim::systems::PosePublisher">
      <use_pose_vector_msg>true</use_pose_vector_msg>
      <static_publisher>true</static_publisher>
      <static_update_frequency>1</static_update_frequency>
      <publish_link_pose>true</publish_link_pose>
      <publish_sensor_pose>true</publish_sensor_pose>
      <publish_collision_pose>false</publish_collision_pose>
      <publish_visual_pose>false</publish_visual_pose>
      <publish_nested_model_pose>true</publish_nested_model_pose>
      <!-- this bit is important -->
      <use_pose_vector_msg>true</use_pose_vector_msg>
      <static_publisher>true</static_publisher>
      <static_update_frequency>1</static_update_frequency>
    </plugin>
    <!-- <plugin
            filename="gz-sim-odometry-publisher-system"
            name="gz::sim::systems::OdometryPublisher">
            <odom_frame>odom</odom_frame>
            <odom_topic>/odom</odom_topic>
            <robot_base_frame>base_link</robot_base_frame>
        </plugin> -->
  </gazebo>
  <joint name="laser_joint" type="fixed">
    <parent link="chassis"/>
    <child link="laser"/>
    <origin rpy="0 0 0" xyz="0.19649999999999998 -0.1075 0.213"/>
  </joint>
  <link name="laser">
    <visual>
      <geometry>
        <cylinder length="0.04" radius="0.019"/>
      </geometry>
      <material name="red"/>
    </visual>
    <collision>
      <geometry>
        <cylinder length="0.04" radius="0.019"/>
      </geometry>
    </collision>
    <inertial>
      <origin rpy="0 0 0" xyz="0 0 0"/>
      <mass value="0.1"/>
      <inertia ixx="2.2358333333333332e-05" ixy="0.0" ixz="0.0" iyy="2.2358333333333332e-05" iyz="0.0" izz="1.805e-05"/>
    </inertial>
  </link>
  <gazebo reference="laser">
    <sensor name="LidarCircularSensor" type="gpu_lidar">
      <pose relative_to="laser_joint">0 0 0.013 0 0 0</pose>
      <topic>/scangz</topic>
      <update_rate>10</update_rate>
      <ray>
        <scan>
          <horizontal>
            <samples>640</samples>
            <resolution>1</resolution>
            <min_angle>-2.14159</min_angle>
            <max_angle>2.14159</max_angle>
          </horizontal>
          <vertical>
            <samples>1</samples>
            <resolution>0.01</resolution>
            <min_angle>0</min_angle>
            <max_angle>0</max_angle>
          </vertical>
        </scan>
        <range>
          <min>0.08</min>
          <max>20.0</max>
          <resolution>0.01</resolution>
        </range>
      </ray>
      <always_on>1</always_on>
      <visualize>true</visualize>
      <!-- <frame_id>lidar</frame_id> -->
    </sensor>
  </gazebo>
  <joint name="gps_joint" type="fixed">
    <parent link="chassis"/>
    <child link="gps"/>
    <origin rpy="0 0 0" xyz="-0.1915 -0.1065 0.29300000000000004"/>
  </joint>
  <link name="gps">
    <visual>
      <geometry>
        <cylinder length="0.02" radius="0.01"/>
      </geometry>
      <material name="red"/>
    </visual>
    <collision>
      <geometry>
        <cylinder length="0.02" radius="0.01"/>
      </geometry>
    </collision>
    <inertial>
      <origin rpy="0 0 0" xyz="0 0 0"/>
      <mass value="0.1"/>
      <inertia ixx="5.833333333333333e-06" ixy="0.0" ixz="0.0" iyy="5.833333333333333e-06" iyz="0.0" izz="5e-06"/>
    </inertial>
  </link>
  <gazebo reference="gps">
    <sensor name="navsat" type="navsat">
      <pose relative_to="gps_joint">0 0 0.013 0 0 0</pose>
      <always_on>1</always_on>
      <update_rate>1</update_rate>
      <topic>/navsat</topic>
    </sensor>
  </gazebo>
  <joint name="imu_joint" type="fixed">
    <parent link="chassis"/>
    <child link="imu"/>
    <origin rpy="0 0 0" xyz="0.041499999999999995 0.0 0.203"/>
  </joint>
  <link name="imu">
    <visual>
      <geometry>
        <box size="0.01 0.01 0.005"/>
      </geometry>
      <material name="red"/>
    </visual>
    <collision>
      <geometry>
        <box size="0.01 0.01 0.005"/>
      </geometry>
    </collision>
    <inertial>
      <origin rpy="0 0 0" xyz="0 0 0"/>
      <mass value="0.001"/>
      <inertia ixx="1.0416666666666667e-08" ixy="0.0" ixz="0.0" iyy="1.0416666666666667e-08" iyz="0.0" izz="1.6666666666666667e-08"/>
    </inertial>
  </link>
  <gazebo reference="imu">
    <sensor name="imu_sensor" type="imu">
      <always_on>1</always_on>
      <update_rate>1</update_rate>
      <visualize>true</visualize>
      <topic>/imu</topic>
    </sensor>
  </gazebo>
  <joint name="collision_joint" type="fixed">
    <parent link="chassis"/>
    <child link="collision_sensor"/>
    <origin rpy="1.5707963267948966 0 0" xyz="0.3165 0 0.07"/>
  </joint>
  <link name="collision_sensor">
    <visual>
      <geometry>
        <cylinder length="0.5" radius="0.01"/>
      </geometry>
      <material name="blue"/>
    </visual>
    <collision>
      <geometry>
        <cylinder length="0.5" radius="0.01"/>
      </geometry>
    </collision>
    <inertial>
      <origin rpy="0 0 0" xyz="0 0 0"/>
      <mass value="0.1"/>
      <inertia ixx="0.0020858333333333336" ixy="0.0" ixz="0.0" iyy="0.0020858333333333336" iyz="0.0" izz="5e-06"/>
    </inertial>
  </link>
  <gazebo reference="collision_sensor">
    <sensor name="sensor_contact" type="contact">
      <contact>
        <collision>collision_sensor</collision>
        <topic>/contact</topic>
      </contact>
      <always_on>1</always_on>
      <update_rate>100</update_rate>
    </sensor>
  </gazebo>
  <joint name="camera_joint" type="fixed">
    <parent link="chassis"/>
    <child link="cam_frame"/>
    <origin rpy="0 0 0" xyz="0.2515 0.003500000000000003 0.1705"/>
  </joint>
  <link name="cam_frame">
    <visual>
      <geometry>
        <box size="0.03 0.1 0.065"/>
      </geometry>
      <material name="blue"/>
    </visual>
    <collision>
      <geometry>
        <box size="0.03 0.1 0.065"/>
      </geometry>
    </collision>
    <inertial>
      <origin rpy="0 0 0" xyz="0 0 0.0325"/>
      <mass value="0.5"/>
      <inertia ixx="0.0005927083333333333" ixy="0.0" ixz="0.0" iyy="0.00021354166666666668" iyz="0.0" izz="0.00045416666666666674"/>
    </inertial>
  </link>
  <gazebo reference="cam_frame">
    <sensor name="Camera" type="camera">
      <!-- 
            https://en.wikipedia.org/wiki/PlayStation_Eye
            -->
      <pose relative_to="camera_joint">0.015 0 0 0 0 0</pose>
      <always_on>1</always_on>
      <update_rate>10</update_rate>
      <topic>/gz_camera/image_raw</topic>
      <camera>
        <horizontal_fov>1.3</horizontal_fov>
        <image>
          <width>640</width>
          <height>480</height>
          <format>R8G8B8</format>
        </image>
        <clip>
          <near>0.1</near>
          <far>1000</far>
        </clip>
        <distortion>
          <k1>-0.383727</k1>
          <k2>0.524611</k2>
          <p1>0.007938</p1>
          <p2>0.033545 </p2>
          <k3>1.991965</k3>
          <center>0.5 0.5</center>
        </distortion>
      </camera>
      <enable_metrics>true</enable_metrics>
    </sensor>
  </gazebo>
  <joint name="laserAS_joint" type="fixed">
    <parent link="chassis"/>
    <child link="lidarAS"/>
    <origin rpy="0 0 0" xyz="-0.1405 0.11649999999999999 0.303"/>
  </joint>
  <link name="lidarAS">
    <visual>
      <geometry>
        <box size="0.032 0.076 0.22"/>
      </geometry>
      <material name="red"/>
    </visual>
    <collision>
      <geometry>
        <box size="0.032 0.076 0.22"/>
      </geometry>
    </collision>
    <inertial>
      <origin rpy="0 0 0" xyz="0 0 0.11"/>
      <mass value="0.5"/>
      <inertia ixx="0.0022573333333333334" ixy="0.0" ixz="0.0" iyy="0.0020541666666666664" iyz="0.0" izz="0.00027816666666666663"/>
    </inertial>
  </link>
  <gazebo reference="lidarAS">
    <sensor name="lidarASCircularSensor" type="gpu_lidar">
      <pose relative_to="laserAS_joint">0.016 0.02 0.03 0 0 0</pose>
      <topic>/lidarAS</topic>
      <update_rate>10</update_rate>
      <ray>
        <scan>
          <horizontal>
            <samples>16</samples>
            <resolution>1</resolution>
            <min_angle>-0.7853975</min_angle>
            <max_angle>0.7853975</max_angle>
          </horizontal>
          <vertical>
            <samples>1</samples>
            <resolution>0.01</resolution>
            <min_angle>0</min_angle>
            <max_angle>0</max_angle>
          </vertical>
        </scan>
        <range>
          <min>0.08</min>
          <max>20.0</max>
          <resolution>0.01</resolution>
        </range>
      </ray>
      <always_on>1</always_on>
      <visualize>true</visualize>
    </sensor>
  </gazebo>
</robot>
